S28800011AAK27GA0000DTS000100SH    0000619200Y
S28800012ABK27GA00000KB001000SSO   0000763800Y
S28800012ABK27GA00000LB001000SSO   0000763600Y
S28800012ABK27GA00000MS001000SSO   0000764800Y
S28800012AAK27GA0000DUS001000SDS   0000549300Y
S28800012AAK27GA0000DVB001000SDS   0000548000Y
S28800012AAK27GA0000DWB000100SPY   0001424100Y
S28800012AAK27GA0000DXS000100SPY   0001426300Y
S28800012AAK27GA0000DYB000100SH    0000618500Y
S28800015AAK27GA0000DZB001000SDS   0000547800Y
S28800075ABK27GA00000NS000100UWM   0000542900Y
S28800075ABK27GA00000OB000100TWM   0000701400Y
S28800075ABK27GA00000PB000100TWM   0000701600Y
S28800075ABK27GA00000QB000100UWM   0000542000Y
S28800075ABK27GA00000RS000100TWM   0000702600Y
S28800075ABK27GA00000SB000100TWM   0000701500Y
S28800136A4K27GA00002RS000100DOG   0000598500Y
S28800137A3K27G6000006S000100DDM   0000802100Y
S28800136A4K27GA00002SS000100DXD   0000501300Y
S28800136A4K27GA00002TS000100DXD   0000501100Y
S28800136A4K27GA00002US000100DXD   0000501200Y
S28800136A4K27GA00002VB000100DXD   0000500400Y
S28800136A4K27GA00002WB000100DOG   0000597200Y
S28800137A3K27G6000007B000100DDM   0000800700Y
S28800161A4K27GA00002XB000100DIG   0001235800Y
S28800161A4K27GA00002YS000100DIG   0001244400Y
S28800160A6K27GA00001IB000100IYE   0001530500Y
S28800160A6K27GA00001JS000100IYE   0001539100Y
S28800162A1K27GA00000VB000100AAPL  0001828600Y
S28800162A1K27GA00000WS000100AAPL  0001834800Y
S28800162A1K27GA00000XB000100AAPL  0001828600Y
S28800162A1K27GA00000YS000100AAPL  0001834800Y
S28800164A9K27G60000CZS001000QID   0000382200Y
S28800164A9K27G60000D0S001000QLD   0000889800Y
S28800164A9K27G60000D1B001000QLD   0000888500Y
S28800164A9K27G60000D2B001000QLD   0000888400Y
S28800164A9K27G60000D3B001000QQQQ  0000495100Y
S28800164A9K27G60000D4B001000QID   0000380900Y
S28800165A9K27G60000D5B000500QQQQ  0000495000Y
S28800165A9K27G60000D6B000500QQQQ  0000494900Y
S28800165A9K27G60000D7B000500QQQQ  0000494400Y
S28800166A9K27G60000D8B000500QQQQ  0000493800Y
S28800166A9K27G60000D9B000500QQQQ  0000494300Y
S28800166A9K27G60000DAB000500QQQQ  0000495100Y
S28800166A9K27G60000DBB000500QQQQ  0000493700Y
S28800166A9K27G60000DCS000500QQQQ  0000496700Y
S28800166A9K27G60000DDS000500QQQQ  0000497300Y
S28800166A9K27G60000DEB000500QQQQ  0000494800Y
S28800166A9K27G60000DFB000500QQQQ  0000494700Y
S28800166A9K27G60000DGB000500QQQQ  0000494100Y
S28800166A9K27G60000DHS000500QQQQ  0000496800Y
S28800166A9K27G60000DIS000500QQQQ  0000497400Y
S28800166A9K27G60000DJB000500QQQQ  0000494500Y
S28800166A9K27G60000DKB000500QQQQ  0000493900Y
S28800166A9K27G60000DLS000500QQQQ  0000496600Y
S28800166A9K27G60000DMS000500QQQQ  0000497200Y
S28800166A9K27G60000DNB000500QQQQ  0000494600Y
S28800166A9K27G60000DOB000500QQQQ  0000494000Y
S28800166A9K27G60000DPS000500QQQQ  0000496400Y
S28800166A9K27G60000DQS000500QQQQ  0000497000Y
S28800166A9K27G60000DRS000500QQQQ  0000497600Y
S28800166A9K27G60000DSB000500QQQQ  0000494200Y
S28800166A9K27G60000DTS000500QQQQ  0000496300Y
S28800166A9K27G60000DUS000500QQQQ  0000496900Y
S28800166A9K27G60000DVS000500QQQQ  0000496500Y
S28800166A9K27G60000DWS000500QQQQ  0000497100Y
S28800166A9K27G60000DXS000500QQQQ  0000497700Y
S28800166A9K27G60000DYS000500QQQQ  0000497500Y
S28800167A4K27GA00002ZB000100DRYS  0001052600Y
S28800168X1K27GA00000Y000100
S28800168A1K27GA00000YS000100AAPL  0001831900Y
S28800168X1K27GA00000V000100
S28800168A1K27GA00000VB000100AAPL  0001826100Y
S28800168X1K27GA00000W000100
S28800168A1K27GA00000WS000100AAPL  0001831900Y
S28800172A9K27G60000DZB001000QQQQ  0000495200Y
S28800172A9K27G60000E0B001000QQQQ  0000495300Y
S28800172A9K27G60000E1B000500QQQQ  0000495200Y
S28800172A9K27G60000E2B000500QQQQ  0000495300Y
S28800173A5K27GA00000JS000100FXP   0000658400Y
S28800174A5K27GA00000KB000100FXP   0000654400Y
S28800174X5K27GA00000K000100
S28800176A5K27GA00000LB000100FXP   0000654200Y
S28800179X5K27GA00000J000100
S28800179A5K27GA00000MB000100FXP   0000656600Y
S28800180X1K27GA00000V000100
S28800180A1K27GA00000VB000100AAPL  0001828600Y
S28800180X1K27GA00000Y000100
S28800180A1K27GA00000YS000100AAPL  0001834800Y
S28800180X1K27GA00000X000100
S28800180A1K27GA00000XB000100AAPL  0001830100Y
S28800180XAK27GA0000DW000100
S28800181X4K27GA00002X000100
S28800179X6K27GA00001I000100
S28800181X1K27GA00000Y000100
S28800181A1K27GA00000YS000100AAPL  0001833400Y
S28800182A9K27G60000E3B001000QQQQ  0000495500Y
S28800182X1K27GA00000Y000100
S28800182A1K27GA00000YS000100AAPL  0001831900Y
S28800183A4K27GA000030B000100DIG   0001235600Y
S28800183AAK27GA0000E0B000100SPY   0001423700Y
S28800182A6K27GA00001KB000100IYE   0001530300Y
S28800185A4K27GA000031B000100DIG   0001237700Y
S28800185X4K27GA000030000100
S28800184A6K27GA00001LB000100IYE   0001531500Y
S28800190ABK27GA00000TS000100UYG   0000322900Y
S28800190A4K27GA000032S000100DRYS  0001071400Y
S28800189A6K27GA00001MS000100IYF   0000860000Y
S28800189A6K27GA00001NS000100IYF   0000859900Y
S28800191A6K27GA00001OB000100IYF   0000853100Y
S28800196A6K27GA00001PS000100IYM   0000877000Y
S28800196A6K27GA00001QB000100IYM   0000869800Y
S28800212A4K27GA000033S000100EEV   0000611400Y
S28800212A4K27GA000034S000100EEM   0001541800Y
S28800272A6K27GA00001RS000100IYR   0000713000Y
S28800274ABK27GA00000UB000100URE   0000371000Y
S28800274ABK27GA00000VS000100URE   0000385600Y
S28800272A6K27GA00001SB000100IYR   0000699000Y
S28800277A9K27G60000E4B001000QLD   0000888600Y
S28800277X9K27G60000D0001000
S28800277X9K27G60000D2001000
S28800277X9K27G60000E3001000
S28800279X9K27G60000E2000500
S28800279X9K27G60000E1000500
S28800279X9K27G60000E0001000
S28800279X9K27G60000DZ001000
S28800279A9K27G60000E5S001000QLD   0000890300Y
S28800279A9K27G60000E6B001000QQQQ  0000495200Y
S28800279A9K27G60000E7S001000QQQQ  0000496100Y
S28800279A9K27G60000E8S001000QQQQ  0000496000Y
S28800279X9K27G60000E8001000
S28800279X9K27G60000E7001000
S28800279A9K27G60000E9B001000QQQQ  0000495300Y
S28800281A9K27G60000EAS000100QID   0000382400Y
S28800282X9K27G60000E6001000
S28800282X9K27G60000D3001000
S28800283A9K27G60000EBS001000QLD   0000890400Y
S28800283X9K27G60000DA000500
S28800283A8K27G6000001S000500MZZ   0000494100Y
S28800284A8K27G6000002B000500MZZ   0000491700Y
S28800284A8K27G6000003S000100MVV   0000809000Y
S28800284A8K27G6000004B000100MVV   0000805900Y
S28800283X4K27GA00002V000100
S28800283A4K27GA000035B000100DXD   0000499600Y
S28800283A4K27GA000036B000100DXD   0000499500Y
S28800285X3K27G6000006000100
S28800285A9K27G60000ECB000500QQQQ  0000493600Y
S28800285A4K27GA000037B000100DXD   0000499700Y
S28800287A3K27G6000008S000100DDM   0000802200Y
S28800297X1K27GA00000Y000100
S28800297A1K27GA00000YS000100AAPL  0001833400Y
S28800301ABK27GA00000WB000100URE   0000372200Y
S28800300X6K27GA00001S000100
S28800300A6K27GA00001TB000100IYR   0000700500Y
S28800311X6K27GA00001T000100
S28800311A6K27GA00001UB000100IYR   0000707000Y
S28800312ABK27GA00000XB000100URE   0000379200Y
S28800318E1K27GA00000X00010000001AQ00001
S28800319X1K27GA00000Y000100
S28800319A1K27GA00000YS000100AAPL  0001831900Y
S28800324X4K27GA00002Z000100
S28800326A4K27GA000038B015000ENCY  0000023300Y
S28800327A4K27GA000039S010930ENCY  0000023500Y
S28800330A8K27G6000005B000500MZZ   0000491800Y
S28800330A3K27G6000009B000100DELL  0000010000Y
S28800340A4K27GA00003AB000100DRYS  0001060800Y
S28800377A6K27GA00001VB000100IYF   0000854200Y
S28800378A6K27GA00001WB000100IYF   0000854100Y
S28800395X5K27GA00000M000100
S28800397A5K27GA00000NB000100FXP   0000656100Y
S28800455X9K27G60000D1001000
S28800457A9K27G60000EDB001000QQQQ  0000495200Y
S28800461X9K27G60000ED001000
S28800499X9K27G60000E4001000
S28800501A9K27G60000EEB001000QLD   0000888400Y
S28800501A9K27G60000EFB001000QQQQ  0000495200Y
S28800511X9K27G60000EF001000
S28800520A9K27G60000EGS000100QLD   0000889700Y
S28800520A9K27G60000EHS001000QQQQ  0000495800Y
S28800520A9K27G60000EIS000500QQQQ  0000496000Y
S28800520A9K27G60000EJS000500QQQQ  0000495900Y
S28800520A9K27G60000EKS000500QQQQ  0000495800Y
S28800531X9K27G60000EI000500
S28800531A9K27G60000ELS001000QQQQ  0000496000Y
S28800531X9K27G60000EH001000
S28800533A9K27G60000EMS001000QQQQ  0000495900Y
S28800561AAK27GA0000E1S000100SKF   0001033900Y
S28800560A6K27GA00001XB000100IYF   0000855100Y
S28800561A6K27GA00001YB000100IYF   0000854900Y
S28800562A6K27GA00001ZB000100IYF   0000854800Y
S28800562X6K27GA00001O000100
S28800582X5K27GA00000N000100
S28800583A5K27GA00000OB000100FXP   0000655800Y
S28800728XAK27GA0000E1000100
S28800727A6K27GA000020B000100IYF   0000855000Y
S28800728AAK27GA0000E2S000100SKF   0001031700Y
S28800728A6K27GA000021B000100IYF   0000855800Y
S28800728X6K27GA00001W000100
S28800729A6K27GA000022B000100IYF   0000855700Y
S28800729X6K27GA00001V000100
S28800758X5K27GA00000O000100
S28800758A5K27GA00000PS000100FXP   0000657300Y
S28801017A6K27GA000023S000100IYF   0000858900Y
S28801018XAK27GA0000E0000100
S28801019AAK27GA0000E3B000100SPY   0001423800Y
S28801019ABK27GA00000YS000100UYG   0000322200Y
S28801018A6K27GA000024S000100IYF   0000860000Y
S28801036AAK27GA0000E4B001000SPY   0001425000Y
S28801036AAK27GA0000E5S001000SPY   0001425200Y
S28801098AAK27GA0000E6S001000SPY   0001425300Y
S28801098AAK27GA0000E7B001000SPY   0001424900Y
S28801105AAK27GA0000E8B001000SPY   0001424800Y
S28801105AAK27GA0000E9S001000SPY   0001425400Y
S28801117AAK27GA0000EAS001000SPY   0001425500Y
S28801117AAK27GA0000EBB001000SPY   0001424700Y
S28801337AAK27GA0000ECB001000SPY   0001425000Y
S28801337AAK27GA0000EDS001000SPY   0001425200Y
S28801435AAK27GA0000EES001000SPY   0001425300Y
S28801435AAK27GA0000EFB001000SPY   0001424900Y
S28801436AAK27GA0000EGS001000SPY   0001425400Y
S28801536AAK27GA0000EHB001000SPY   0001424800Y
S28801537AAK27GA0000EIS001000SPY   0001425500Y
S28801560A9K27G60000ENS002000QQQQ  0000495700Y
S28801560A9K27G60000EOB002000QQQQ  0000495500Y
S28801574AAK27GA0000EJB001000SPY   0001424700Y
S28801660A9K27G60000EPB002000QQQQ  0000495400Y
S28801660A9K27G60000EQS002000QQQQ  0000495800Y
S28801697A9K27G60000ERB005000QQQQ  0000495500Y
S28801697A9K27G60000ESS005000QQQQ  0000495700Y
S28801761A9K27G60000ETS002000QQQQ  0000495900Y
S28801761A9K27G60000EUB002000QQQQ  0000495300Y
S28801797A9K27G60000EVS005000QQQQ  0000495800Y
S28801797A9K27G60000EWB005000QQQQ  0000495400Y
S28801897A9K27G60000EXB005000QQQQ  0000495300Y
S28801897A9K27G60000EYS005000QQQQ  0000495900Y
S28801914A1K27GA000011B000100AAPL  0001828600Y
S28801997A9K27G60000EZB005000QQQQ  0000495200Y
S28801997A9K27G60000F0S005000QQQQ  0000496000Y
S28802100X1K27GA000011000100
S28802100A1K27GA000011B000100AAPL  0001830100Y
S28802322A9K27G60000F1B003200QQQQ  0000495500Y
S28802322A9K27G60000F2S003200QQQQ  0000495700Y
S28802408A6K27GA000025B000500IWM   0000736200Y
S28802408A6K27GA000026S000500IWM   0000736500Y
S28802424A9K27G60000F3B003200QQQQ  0000495400Y
S28802424A9K27G60000F4S003200QQQQ  0000495800Y
S28802439A6K27GA000027B000500IWM   0000736100Y
S28802439A6K27GA000028S000500IWM   0000736600Y
S28802465A9K27G60000F5B003200QQQQ  0000495300Y
S28802465A9K27G60000F6S003200QQQQ  0000495900Y
S28802465X1K27GA000011000100
S28802465A1K27GA000011B000100AAPL  0001828600Y
S28802520X4K27GA00003A000100
S28802522A9K27G60000F7B003200QQQQ  0000495200Y
S28802522A9K27G60000F8S003200QQQQ  0000496000Y
S28802537A4K27GA00003BB000100DRYS  0001065100Y
S28802568X4K27GA00002T000100
S28802568X4K27GA000037000100
S28802568A4K27GA00003CS000100DXD   0000500400Y
S28802570A4K27GA00003DB000100DXD   0000499400Y
S28802575X4K27GA00002W000100
S28802576A4K27GA00003EB000100DOG   0000597100Y
S28802623A9K27G60000F9B003200QQQQ  0000495100Y
S28802623A9K27G60000FAS003200QQQQ  0000496100Y
S28802661XAK27GA0000E5001000
S28802661AAK27GA0000E5S001000SPY   0001425600Y
S28802666XAK27GA0000DV001000
S28802667XBK27GA00000M001000
S28802668AAK27GA0000EKB001000SDS   0000547900Y
S28802669ABK27GA00000ZS001000SSO   0000764900Y
S28802672A6K27GA000029B000500IWM   0000736000Y
S28802672A6K27GA00002AS000500IWM   0000736700Y
S28802676A6K27GA00002BS000500IWM   0000736800Y
S28802676A6K27GA00002CB000500IWM   0000735900Y
S28802682A9K27G60000FBB001000QLD   0000888600Y
S28802682X9K27G60000EE001000
S28802685A9K27G60000FCB001000QQQQ  0000495200Y
S28802688X9K27G60000F2003200
S28802688A9K27G60000F2S003200QQQQ  0000496200Y
S28802688X9K27G60000EZ005000
S28802690A9K27G60000FDB001000QLD   0000888500Y
S28802694A9K27G60000FEB005000QQQQ  0000495600Y
S28802694X9K27G60000FC001000
S28802858AAK27GA0000ELB003000SPY   0001424900Y
S28802858AAK27GA0000EMS003000SPY   0001425400Y
S28802864AAK27GA0000ENB003000SPY   0001424700Y
S28802864AAK27GA0000EOS003000SPY   0001425600Y
S28802866AAK27GA0000EPB003000SPY   0001424500Y
S28802866AAK27GA0000EQS003000SPY   0001425800Y
S28802903XAK27GA0000ED001000
S28802917XAK27GA0000EB001000
S28802917AAK27GA0000EBB001000SPY   0001425100Y
S28802917XAK27GA0000EJ001000
S28802918AAK27GA0000ERS001000SPY   0001425600Y
S28802918AAK27GA0000ESB000900SPY   0001425100Y
S28802918AAK27GA0000ETB003000SPY   0001424900Y
S28802918AAK27GA0000EUS003000SPY   0001425400Y
S28802919AAK27GA0000EVS000100SH    0000619100Y
S28802920XBK27GA00000K001000
S28802920ABK27GA000010B001000SSO   0000763900Y
S28802922XBK27GA00000L001000
S28802922ABK27GA000011B001000SSO   0000763700Y
S28802926AAK27GA0000EWS000500SPY   0001425300Y
S28802926AAK27GA0000EXB000500SPY   0001425000Y
S28802926AAK27GA0000EYS003000SPY   0001425600Y
S28802926AAK27GA0000EZB003000SPY   0001424700Y
S28802953AAK27GA0000F0S003000SPY   0001425800Y
S28802953AAK27GA0000F1B003000SPY   0001424500Y
S28802953AAK27GA0000F2B000500SPY   0001424900Y
S28802953AAK27GA0000F3S000500SPY   0001425400Y
S28802980AAK27GA0000F4S000500SPY   0001425500Y
S28802980AAK27GA0000F5B000500SPY   0001424800Y
S28802995AAK27GA0000F6S000500SPY   0001425600Y
S28802995AAK27GA0000F7B000500SPY   0001424700Y
S28803036XAK27GA0000DY000100
S28803036XAK27GA0000EK001000
S28803036XBK27GA00000Z001000
S28803037AAK27GA0000F8B000100SH    0000618400Y
S28803038AAK27GA0000F9B001000SDS   0000547800Y
S28803038ABK27GA000012S001000SSO   0000765000Y
S28803047XAK27GA0000DZ001000
S28803219A4K27GA00003FS000100DXD   0000500500Y
S28803219A4K27GA00003GS000200DIA   0001298500Y
S28803219A4K27GA00003HB000200DIA   0001298300Y
S28803221A4K27GA00003IS000100DXD   0000500600Y
S28803221A4K27GA00003JB000100DOG   0000597200Y
S28803221A3K27G600000AS000100DDM   0000802100Y
S28803221A4K27GA00003KB000100DXD   0000499700Y
S28803222A4K27GA00003LB000200DIA   0001298200Y
S28803222A4K27GA00003MS000200DIA   0001298600Y
S28803224X3K27G6000008000100
S28803224X3K27G600000A000100
S28803224E4K27GA00003G00007700004AQ00001
S28803224E4K27GA00003G00007600004AQ00002
S28803225X4K27GA00003J000100
S28803226A3K27G600000BS000100DDM   0000802200Y
S28803226X4K27GA00003K000100
S28803228A4K27GA00003PB000100DXD   0000499700Y
S28803234X4K27GA00003P000100
S28803238X4K27GA00003G000047
S28803238A4K27GA00003QB000200DIA   0001298100Y
S28803240P4K27GA00003PB000100DXD   0000499600000N4AQ00003
S28803247X4K27GA00003C000100
S28803247X3K27G6000007000100
S28803247X4K27GA00002R000100
S28803248A4K27GA00003RS000100DXD   0000500700Y
S28803249A3K27G600000CB000100DDM   0000800600Y
S28803249A4K27GA00003SS000100DOG   0000598600Y
S28803685XAK27GA0000F7000500
S28803685AAK27GA0000F7B000500SPY   0001425100Y
S28803869A9K27G60000FFS005000QQQQ  0000495700Y
S28803869A9K27G60000FGB005000QQQQ  0000495500Y
S28803968A9K27G60000FHB005000QQQQ  0000495400Y
S28803968A9K27G60000FIS005000QQQQ  0000495800Y
S28804068A9K27G60000FJB005000QQQQ  0000495300Y
S28804068A9K27G60000FKS005000QQQQ  0000495900Y
S28804168A9K27G60000FLB005000QQQQ  0000495200Y
S28804168A9K27G60000FMS005000QQQQ  0000496000Y
S28804485A4K27GA00003TS000100DOG   0000598500Y
S28804485X4K27GA00002S000100
S28804485A4K27GA00003US000100DXD   0000500400Y
S28804485A3K27G600000DB000100DDM   0000800700Y
S28804999XAK27GA0000EW000500
S28804999AAK27GA0000EWS000500SPY   0001425700Y
S28805083A9K27G60000FNS002000QQQQ  0000495700Y
S28805083A9K27G60000FOB002000QQQQ  0000495500Y
S28805183A9K27G60000FPS002000QQQQ  0000495800Y
S28805614XAK27GA0000EW000500
S28805614AAK27GA0000EWS000500SPY   0001425300Y
S28805824A9K27G60000FQB002000QQQQ  0000495600Y
S28805824X9K27G60000FL005000
S28805825A9K27G60000FRB005000QQQQ  0000495600Y
S28805826X9K27G60000EU002000
S28805826A9K27G60000EUB002000QQQQ  0000495600Y
S28805962A8K27G6000006B002000MSFT  0000282700Y
S28806390A1K27GA000012B002000AMAT  0000182900Y
S28806429A1K27GA000013B002000AMGN  0000413600Y
S28806448A1K27GA000014B002000AMZN  0000796800Y
S28806466A2K27G600000FB002000BRCM  0000259400Y
S28806486A3K27G600000EB002000CELG  0000454800Y
S28806510A3K27G600000FB002000CHKP  0000231700Y
S28806531A3K27G600000GB002000CREE  0000237300Y
S28806556A3K27G600000HB002000CYMI  0000285200Y
S28806574A4K27GA00003VB002000DISH  0000320300Y
S28806603A4K27GA00003WB002000DRIV  0000358300Y
S28806794AAK27GA0000FAB000600SPY   0001419600Y
S28806923AAK27GA0000FBS000100SKF   0001031400Y
S28806923XAK27GA0000E2000100
S28806922A6K27GA00002DB000100IYF   0000855300Y
S28806922X6K27GA00001X000100
S28806923X6K27GA00001Z000100
S28806923A6K27GA00002EB000100IYF   0000855900Y
S28806925AAK27GA0000FCS000500SPY   0001425400Y
S28806925AAK27GA0000FDB000500SPY   0001425000Y
S28806927AAK27GA0000FEB000500SPY   0001424900Y
S28806927AAK27GA0000FFS000500SPY   0001425500Y
S28806928AAK27GA0000FGB000500SPY   0001424800Y
S28806928AAK27GA0000FHS000500SPY   0001425600Y
S28806930AAK27GA0000FIB000500SPY   0001424700Y
S28806930AAK27GA0000FJS000500SPY   0001425700Y
S28806960X1K27GA000011000100
S28806960A1K27GA000011B000100AAPL  0001830100Y
S28807196E5K27GA00000L00002000005AQ00001
S28807197X5K27GA00000P000100
S28807197X5K27GA00000L000080
S28807197A5K27GA00000RS000100FXP   0000657100Y
S28807199A5K27GA00000SB000100FXP   0000654100Y
S28807216E5K27GA00000S00010000005AQ00002
S28807218A5K27GA00000UB000100FXP   0000652500Y
S28807220X5K27GA00000U000100
S28807222A5K27GA00000VB000100FXP   0000652500Y
S28807224X5K27GA00000V000100
S28807225A5K27GA00000WB000100FXP   0000651400Y
S28807226A5K27GA00000XB000100FXP   0000652500Y
S28807239E5K27GA00000X00010000005AQ00003
S28807241X5K27GA00000W000100
S28807242A5K27GA00000ZB000100FXP   0000652300Y
S28807274A4K27GA00003XS000200DIA   0001298700Y
S28807386A4K27GA00003YB002000EBAY  0000292900Y
S28807423A4K27GA00003ZB002000ENZN  0000069500Y
S28807440A5K27GA000010B002000GILD  0000515700Y
S28807456A5K27GA000011B002000IACI  0000220300Y
S28807472A6K27GA00002FB002000IMCL  0000285600Y
S28807478A6K27GA00002GB002000INTC  0000237800Y
S28807492A6K27GA00002HB002000INTU  0000256400Y
S28807506A7K27GA00000KB002000MRVL  0000135200Y
S28807520A8K27G6000007B002000NFLX  0000308000Y
S28807528PCK27GA000016B000177ZVZZT 0020000000000I000HV1PJ
S28807529PCK27GA000016B000100ZVZZT 0020000000000I000HV1PK
S28807529PCK27GA000016B000100ZVZZT 0020000000000I000HV1PL
S28807959AAK27GA0000FKB002000SAP   0000470900Y
S28807982A1K27GA000015B002000A     0000345100Y
S28808228X9K27G60000ES005000
S28808228X9K27G60000FF005000
S28808229X9K27G60000EN002000
S28808229A9K27G60000ENS002000QQQQ  0000496000Y
S28808230A9K27G60000FSS005000QQQQ  0000496100Y
S28808230A9K27G60000FTS005000QQQQ  0000496100Y
S28808393A1K27GA000016B002000AA    0000431500Y
S28808420A9K27G60000FUB002000QCOM  0000457300Y
S28808443A1K27GA000017B002000ADI   0000339700Y
S28808446A4K27GA000040S000047DIA   0001298800Y
S28808453A9K27G60000FVB002000QLGC  0000144200Y
S28808485A1K27GA000018B002000ADP   0000419000Y
S28808495AAK27GA0000FLB002000SHLD  0000604900Y
S28808513A1K27GA000019B002000AIG   0000371800Y
S28808528AAK27GA0000FMB002000SINA  0000507400Y
S28808550AAK27GA0000FNB002000SMTC  0000162200Y
S28808553A1K27GA00001AB002000APA   0001428400Y
S28808590AAK27GA0000FOB002000SOHU  0000796000Y
S28808605A2K27G600000GB002000BAC   0000347300Y
S28808623ABK27GA000013B002000SYMC  0000195200Y
S28808633A2K27G600000HB002000BRL   0000370400Y
S28808654ABK27GA000014B002000TTWO  0000254000Y
S28808666A2K27G600000IB002000C     0000218900Y
S28808720A3K27G600000IB002000COF   0000495200Y
S28808736A4K27GA000041B002000DNA   0000685300Y
S28809385X6K27GA00002F002000
S28809418XAK27GA0000FL002000
S28809425A4K27GA000042B002000DVN   0001208500Y
S28809462ACK27GA000017B002000VSEA  0000373100Y
S28809489A4K27GA000043B002000EMR   0000551000Y
S28809502ACK27GA000018B002000WFMI  0000275300Y
S28809539A5K27GA000012B002000FNM   0000275800Y
S28809539A1K27GA00001BB002000AA    0000432300Y
S28809550ACK27GA000019B002000XLNX  0000254400Y
S28809581A5K27GA000013B002000GG    0000384100Y
S28809606A1K27GA00001CB002000ADI   0000340500Y
S28809644A5K27GA000014B002000GM    0000171100Y
S28809649ACK27GA00001AB002000YHOO  0000265100Y
S28809671A1K27GA00001DB002000ADP   0000419800Y
S28809707A1K27GA00001EB002000AAPL  0001816400Y
S28809708A5K27GA000015B002000GS    0001816500Y
S28809744A1K27GA00001FB002000AIG   0000372600Y
S28809755A6K27GA00002IB002000IBM   0001246600Y
S28809791A1K27GA00001GB002000ADSK  0000384200Y
S28809807A1K27GA00001HB002000APA   0001429200Y
S28809830A6K27GA00002JB002000JNJ   0000638000Y
S28809840A1K27GA00001IB002000ADTN  0000228200Y
S28809877A7K27GA00000LB002000KSS   0000453000Y
S28809892A2K27G600000JB002000BAC   0000348200Y
S28809901A1K27GA00001JB002000ALTR  0000211400Y
S28809928A7K27GA00000MB002000LMT   0000020300Y
S28809989A2K27G600000KB002000C     0000219700Y
S28810016A3K27G600000JB002000COF   0000496000Y
S28810038A4K27GA000044B002000DNA   0000686100Y
S28810393X7K27GA00000M002000
S28810459A7K27GA00000NB002000MDT   0000477800Y
S28810459A4K27GA000045B002000DVN   0001209300Y
S28810461A6K27GA00002KB002000IMCL  0000288900Y
S28810470A7K27GA00000OB002000MMM   0000762000Y
S28810482AAK27GA0000FPS001000SPY   0001425400Y
S28810482AAK27GA0000FQB001000SPY   0001424900Y
S28810482AAK27GA0000FRB002000SHLD  0000610000Y
S28810494A4K27GA000046B002000EMR   0000551800Y
S28810536A7K27GA00000PB002000MO    0000211600Y
S28810538A1K27GA00001KB002000APOL  0000403200Y
S28810579A1K27GA00001LB002000APPX  0000092400Y
S28810581A8K27G6000008B002000NBR   0000402800Y
S28810581A5K27GA000016B002000FNM   0000276600Y